{\rtf1\ansi\ansicpg1252\cocoartf2639
\cocoatextscaling0\cocoaplatform0{\fonttbl\f0\fswiss\fcharset0 Helvetica;}
{\colortbl;\red255\green255\blue255;}
{\*\expandedcolortbl;;}
\paperw11900\paperh16840\margl1440\margr1440\vieww11520\viewh8400\viewkind0
\pard\tx566\tx1133\tx1700\tx2267\tx2834\tx3401\tx3968\tx4535\tx5102\tx5669\tx6236\tx6803\pardirnatural\partightenfactor0

\f0\fs24 \cf0 <?xml version="1.0" ?>\
<sdf version="1.6">\
  <model name="car_model">\
    <static>false</static>  <!-- Robot can move -->\
    <pose>0 0 0 0 0 0</pose>\
\
    <!-- Car chassis -->\
    <link name="chassis">\
      <pose>0 0 0.2 0 0 0</pose>  <!-- Position above ground -->\
      <inertial>\
        <mass>80</mass>\
        <inertia>\
          <ixx>10</ixx> <iyy>10</iyy> <izz>10</izz>\
        </inertia>\
      </inertial>\
\
      <!-- Visual representation of the chassis -->\
      <visual name="chassis_visual">\
        <geometry>\
          <box>\
            <size>1.5 1.0 0.5</size>  <!-- Dimensions of the car body -->\
          </box>\
        </geometry>\
        <material>\
          <ambient>0.0 0.5 0.5 1.0</ambient>\
          <diffuse>0.0 0.5 0.5 1.0</diffuse>\
        </material>\
      </visual>\
\
      <!-- Collision properties for the chassis -->\
      <collision name="chassis_collision">\
        <geometry>\
          <box>\
            <size>1.5 1.0 0.5</size>\
          </box>\
        </geometry>\
      </collision>\
    </link>\
\
    <!-- Front left wheel -->\
    <link name="front_left_wheel">\
      <pose>0.7 0.6 0.1 0 0 0</pose>\
      <inertial>\
        <mass>1</mass>\
        <inertia>\
          <ixx>0.1</ixx> <iyy>0.1</iyy> <izz>0.1</izz>\
        </inertia>\
      </inertial>\
\
      <visual name="wheel_visual">\
        <geometry>\
          <cylinder>\
            <radius>0.2</radius>\
            <length>0.1</length>\
          </cylinder>\
        </geometry>\
        <material>\
          <ambient>0.1 0.1 0.1 1.0</ambient>\
          <diffuse>0.1 0.1 0.1 1.0</diffuse>\
        </material>\
      </visual>\
\
      <collision name="wheel_collision">\
        <geometry>\
          <cylinder>\
            <radius>0.2</radius>\
            <length>0.1</length>\
          </cylinder>\
        </geometry>\
      </collision>\
    </link>\
\
    <!-- Joint for front left wheel -->\
    <joint name="front_left_wheel_joint" type="revolute">\
      <parent>chassis</parent>\
      <child>front_left_wheel</child>\
      <axis>\
        <xyz>0 1 0</xyz>\
        <limit>\
          <lower>-1.0</lower>\
          <upper>1.0</upper>\
        </limit>\
      </axis>\
    </joint>\
\
    <!-- Front right wheel (similar to front left) -->\
    <link name="front_right_wheel">\
      <pose>0.7 -0.6 0.1 0 0 0</pose>\
      <inertial>\
        <mass>1</mass>\
        <inertia>\
          <ixx>0.1</ixx> <iyy>0.1</iyy> <izz>0.1</izz>\
        </inertia>\
      </inertial>\
      <visual name="wheel_visual">\
        <geometry>\
          <cylinder>\
            <radius>0.2</radius>\
            <length>0.1</length>\
          </cylinder>\
        </geometry>\
        <material>\
          <ambient>0.1 0.1 0.1 1.0</ambient>\
          <diffuse>0.1 0.1 0.1 1.0</diffuse>\
        </material>\
      </visual>\
      <collision name="wheel_collision">\
        <geometry>\
          <cylinder>\
            <radius>0.2</radius>\
            <length>0.1</length>\
          </cylinder>\
        </geometry>\
      </collision>\
    </link>\
\
    <!-- Joint for front right wheel -->\
    <joint name="front_right_wheel_joint" type="revolute">\
      <parent>chassis</parent>\
      <child>front_right_wheel</child>\
      <axis>\
        <xyz>0 1 0</xyz>\
        <limit>\
          <lower>-1.0</lower>\
          <upper>1.0</upper>\
        </limit>\
      </axis>\
    </joint>\
\
    <!-- Rear left wheel -->\
    <link name="rear_left_wheel">\
      <pose>-0.7 0.6 0.1 0 0 0</pose>\
      <inertial>\
        <mass>1</mass>\
        <inertia>\
          <ixx>0.1</ixx> <iyy>0.1</iyy> <izz>0.1</izz>\
        </inertia>\
      </inertial>\
      <visual name="wheel_visual">\
        <geometry>\
          <cylinder>\
            <radius>0.2</radius>\
            <length>0.1</length>\
          </cylinder>\
        </geometry>\
        <material>\
          <ambient>0.1 0.1 0.1 1.0</ambient>\
          <diffuse>0.1 0.1 0.1 1.0</diffuse>\
        </material>\
      </visual>\
      <collision name="wheel_collision">\
        <geometry>\
          <cylinder>\
            <radius>0.2</radius>\
            <length>0.1</length>\
          </cylinder>\
        </geometry>\
      </collision>\
    </link>\
\
    <!-- Joint for rear left wheel -->\
    <joint name="rear_left_wheel_joint" type="revolute">\
      <parent>chassis</parent>\
      <child>rear_left_wheel</child>\
      <axis>\
        <xyz>0 1 0</xyz>\
        <limit>\
          <lower>-1.0</lower>\
          <upper>1.0</upper>\
        </limit>\
      </axis>\
    </joint>\
\
    <!-- Rear right wheel -->\
    <link name="rear_right_wheel">\
      <pose>-0.7 -0.6 0.1 0 0 0</pose>\
      <inertial>\
        <mass>1</mass>\
        <inertia>\
          <ixx>0.1</ixx> <iyy>0.1</iyy> <izz>0.1</izz>\
        </inertia>\
      </inertial>\
      <visual name="wheel_visual">\
        <geometry>\
          <cylinder>\
            <radius>0.2</radius>\
            <length>0.1</length>\
          </cylinder>\
        </geometry>\
        <material>\
          <ambient>0.1 0.1 0.1 1.0</ambient>\
          <diffuse>0.1 0.1 0.1 1.0</diffuse>\
        </material>\
      </visual>\
      <collision name="wheel_collision">\
        <geometry>\
          <cylinder>\
            <radius>0.2</radius>\
            <length>0.1</length>\
          </cylinder>\
        </geometry>\
      </collision>\
    </link>\
\
    <!-- Joint for rear right wheel -->\
    <joint name="rear_right_wheel_joint" type="revolute">\
      <parent>chassis</parent>\
      <child>rear_right_wheel</child>\
      <axis>\
        <xyz>0 1 0</xyz>\
        <limit>\
          <lower>-1.0</lower>\
          <upper>1.0</upper>\
        </limit>\
      </axis>\
    </joint>\
\
    <!-- LIDAR (Velodyne) sensor for obstacle detection -->\
    <link name="lidar_link">\
      <pose>0 0 0.5 0 0 0</pose> <!-- Position on top of the robot -->\
      <sensor name="lidar" type="gpu_ray">\
        <update_rate>10</update_rate>\
        <ray>\
          <scan>\
            <horizontal>\
              <samples>720</samples>\
              <resolution>1</resolution>\
              <min_angle>-1.57</min_angle>\
              <max_angle>1.57</max_angle>\
            </horizontal>\
          </scan>\
          <range>\
            <min>0.2</min>\
            <max>10.0</max> <!-- Range of the LIDAR -->\
          </range>\
        </ray>\
      </sensor>\
    </link>\
  </model>\
</sdf>\
}